<?xml version="1.0"?>

<!-- Robot Description format of CLAM arm
Dave Coleman - davetcoleman@gmail.com, 10/23/13

Nicolas Alt, 2014-08-21

Documentation:

URDF
http://www.ros.org/wiki/urdf/XML

XARCO - Macro Language
http://www.ros.org/wiki/xacro

-->
<robot name="lmtclam" xmlns:xacro="http://www.ros.org/wiki/xacro">

  <!-- Include URDFs -->
  <xacro:include filename="$(find lmtclam)/model/materials.urdf.xacro" />

  <!-- Constants -->
  <property name="M_SCALE" value="0.001 0.001 0.001"/>
  <property name="M_PI" value="3.141592653589793"/>

  <!-- TABLETOP LINK -->
  <joint name="tabletop_joint" type="fixed">
    <origin xyz="0 0 0" rpy="${-M_PI/2} ${-M_PI/2} 0" />
    <!-- Rotate the coordinate system:
         tabletop_link: plane spanned by x-y, z goes up
         arm_base_link: x along arm, y to front, x to left -->
    <parent link="tabletop_link"/>
    <child link="arm_base_link"/>
  </joint>

  <link name="tabletop_link">

    <inertial>
      <origin xyz="0 0 -0.017"/>
      <mass value="100.0" />
      <inertia  ixx="1.0" ixy="0.0"  ixz="0.0"  iyy="100.0"  iyz="0.0"  izz="1.0" />
    </inertial>

    <!-- visual>
      <origin xyz=" 0 0 -0.017"  rpy="${.5*M_PI} 0 ${.5*M_PI}"/>
      <geometry>
        <mesh filename="package://lmtclam/model/stl/tabletop_link.STL" scale="${M_SCALE}" />
      </geometry>
      <material name="Brown" />
    </visual -->

    <!-- collision>
      <origin xyz=" 0 0 -0.017"  rpy="${.5*M_PI} 0 ${.5*M_PI}"/>
      <geometry>
        <mesh filename="package://lmtclam/model/stl/tabletop_link_simple.STL" scale="${M_SCALE}" />
      </geometry>
      </collision> -->

  </link>

  <gazebo reference="tabletop_link">
    <material>Gazebo/White</material>
  </gazebo>

  <!-- BASE LINK -->
  <link name="arm_base_link">

    <!--inertial>
        <origin xyz="0 0 0" />
        <mass value="1.0" />
        <inertia  ixx="1.0" ixy="0.0"  ixz="0.0"  iyy="100.0"  iyz="0.0"  izz="1.0" />
        </inertial-->

    <visual>
      <origin xyz="0 0 0" rpy="0 0 ${-M_PI/2}" oldrpy="${M_PI/2} 0 0" /> <!-- rotate PI/2 -->
      <geometry>
        <mesh filename="package://lmtclam/model/stl/base_link.STL" scale="${M_SCALE}" />
      </geometry>
      <material name="Grey" />
    </visual>

    <collision>
      <origin xyz="0 0 0" rpy="0 0 ${-M_PI/2}" oldrpy="${M_PI/2} 0 0" /> <!-- rotate PI/2 -->
      <geometry>
        <mesh filename="package://lmtclam/model/stl/base_link_simple.STL" scale="${M_SCALE}" />
      </geometry>
      </collision>>

  </link>

  <gazebo reference="arm_base_link">
    <material>Gazebo/Grey</material>
  </gazebo>

  <joint name="joint0" type="revolute">
    <parent link="arm_base_link"/>
    <child link="shoulder_pan_link"/>
    <origin xyz="0.05 0 0" rpy="0 0 0" />
    <axis xyz="1 0 0" />
    <limit effort="300" velocity="1" lower="${-M_PI}" upper="${M_PI}"/>
    <dynamics damping="50" friction="1"/>
  </joint>

  <!-- SHOULDER PAN LINK -->
  <link name="shoulder_pan_link" >

    <inertial>
      <origin xyz="0 0 0" />
      <mass value="1.0" />
      <inertia  ixx="1.0" ixy="0.0"  ixz="0.0"  iyy="100.0"  iyz="0.0"  izz="1.0" />
    </inertial>

    <visual>
      <origin xyz="0 0 0" rpy="${M_PI/2} ${M_PI/2} 0" oldrpy="0 0 ${M_PI/2}" />
      <geometry>
        <mesh filename="package://lmtclam/model/stl/shoulder_pan_link.STL" scale="${M_SCALE}" />
      </geometry>
      <material name="Orange" />
    </visual>

    <collision>
      <origin xyz="0 0 0" rpy="${M_PI/2} ${M_PI/2} 0" oldrpy="0 0 ${M_PI/2}" />
      <geometry>
        <mesh filename="package://lmtclam/model/stl/shoulder_pan_link_simple.STL" scale="${M_SCALE}" />
      </geometry>
    </collision>
  </link>

  <gazebo reference="shoulder_pan_link">
    <material>Gazebo/Orange</material>
  </gazebo>

  <joint name="joint1" type="revolute">
    <parent link="shoulder_pan_link"/>
    <child link="shoulder_pitch_link"/>
    <!-- todo: why 0.0021?? -->
    <origin xyz="0.041 0.0 0.0" oldxyz="-0.041 0.0021 0.0" rpy="0 0 0" oldrpy="-${M_PI/2} 0 ${M_PI/2}" />
    <axis xyz="0 0 -1" /> <!-- modified! -->
    <limit effort="300" velocity="1" lower="-1.8" upper="1.25" />
    <dynamics damping="50" friction="1"/>
  </joint>

  <!-- SHOULDER PITCH LINK -->
  <link name="shoulder_pitch_link" >

    <inertial>
      <origin xyz="-0.002 0 -0.000"  />
      <mass value="1.0" />
      <inertia  ixx="1.0" ixy="0.0"  ixz="0.0"  iyy="100.0"  iyz="0.0"  izz="1.0" />
    </inertial>

    <visual>
      <origin xyz="-0.002 0 -0.000" rpy="0 0 ${M_PI/2}" oldrpy="${M_PI/2} ${M_PI} ${M_PI/2}" />
      <geometry>
        <mesh filename="package://lmtclam/model/stl/shoulder_pitch_link.STL" scale="${M_SCALE}" />
      </geometry>
      <material name="Grey" />
    </visual>

    <collision>
      <origin xyz="-0.002 0 -0.000" rpy="0 0 ${M_PI/2}" />
      <geometry>
        <mesh filename="package://lmtclam/model/stl/shoulder_pitch_link_simple.STL" scale="${M_SCALE}" />
      </geometry>
    </collision>

  </link>

  <gazebo reference="shoulder_pitch_link">
    <material>Gazebo/Grey</material>
  </gazebo>

  <joint name="joint2" type="revolute">
    <parent link="shoulder_pitch_link"/>
    <child link="elbow_roll_link"/>
    <origin xyz="0.12 0.0 0" rpy="0 0 0" oldxyz="-0.002 0 0.1206" oldrpy="${M_PI} ${M_PI/2} 0" />
    <axis xyz="1 0 0" />
    <limit effort="300" velocity="1" lower="${-M_PI}" upper="${M_PI}" />
    <dynamics damping="50" friction="1"/>
  </joint>

  <!-- ELBOW ROLL LINK -->
  <link name="elbow_roll_link" >

    <inertial>
      <origin xyz="-0.035 0.0 0.0"  />
      <mass value="1.0" />
      <inertia  ixx="1.0" ixy="0.0"  ixz="0.0"  iyy="100.0"  iyz="0.0"  izz="1.0" />
    </inertial>

    <visual>
      <origin xyz="0.035 0.0 0.0" rpy="${M_PI/2} ${M_PI/2} ${M_PI}" oldrpy="${M_PI} ${M_PI/2} ${M_PI/2}" />
      <geometry>
        <mesh filename="package://lmtclam/model/stl/elbow_roll_link.STL" scale="${M_SCALE}" />
      </geometry>
      <material name="Black" />
    </visual>

    <collision>
      <origin xyz="0.035 0.0 0.0" rpy="${M_PI/2} ${M_PI/2} ${M_PI}" />
      <geometry>
        <mesh filename="package://lmtclam/model/stl/elbow_roll_link_simple.STL" scale="${M_SCALE}" />
      </geometry>
    </collision>

  </link>

  <gazebo reference="elbow_roll_link">
    <material>Gazebo/Black</material>
  </gazebo>

  <joint name="joint3" type="revolute">
    <parent link="elbow_roll_link"/>
    <child link="elbow_pitch_link"/>
    <origin xyz="0.035 0 0.0" rpy="0.0 0 0" oldxyz="-0.035 0 0.0" oldrpy="0.0 ${M_PI/2} 0" />
    <axis xyz="0 0 1" />
    <limit effort="300" velocity="1" lower="-1.59" upper="1.93" />
    <dynamics damping="50" friction="1"/>
  </joint>


  <!-- ELBOW PITCH LINK -->
  <link name="elbow_pitch_link" >

    <inertial>
      <origin xyz="0.0 0 0"  />
      <mass value="1.0" />
      <inertia  ixx="1.0" ixy="0.0"  ixz="0.0"  iyy="100.0"  iyz="0.0"  izz="1.0" />
    </inertial>

    <visual>
      <origin xyz="0.0 0 0" rpy="${M_PI} 0 ${-M_PI/2} " oldrpy="${M_PI/2} 0 ${M_PI/2+M_PI}" />
      <geometry>
        <mesh filename="package://lmtclam/model/stl/elbow_pitch_link.STL" scale="${M_SCALE}" />
      </geometry>
      <material name="Orange" />
    </visual>

    <collision>
      <origin xyz="0.0 0 0" rpy="${M_PI} 0 ${-M_PI/2} " />
      <geometry>
        <mesh filename="package://lmtclam/model/stl/elbow_pitch_link_simple.STL" scale="${M_SCALE}" />
      </geometry>
    </collision>

  </link>

  <gazebo reference="elbow_pitch_link">
    <material>Gazebo/Orange</material>
  </gazebo>

  <joint name="joint4" type="revolute">
    <parent link="elbow_pitch_link"/>
    <child link="wrist_roll_link"/>
    <origin xyz="0.248 0.008 0" rpy="0 0 0" oldxyz="0.0 0.0081 -.248" oldrpy="0 ${M_PI/2} ${M_PI}" />
    <!-- Includes Bracket height: 30mm (from drawing) -->
    <axis xyz="1 0 0" />
    <limit effort="300" velocity="1" lower="${-M_PI}" upper="${M_PI}" />
    <dynamics damping="50" friction="1"/>
  </joint>

  <!-- WRIST ROLL LINK -->
  <link name="wrist_roll_link" >

    <inertial>
      <origin xyz="0 0 0"  />
      <mass value="1.0" />
      <inertia  ixx="1.0" ixy="0.0"  ixz="0.0"  iyy="100.0"  iyz="0.0"  izz="1.0" />
    </inertial>

    <visual>
      <origin xyz="0 0 0" rpy="0 ${M_PI/2} ${M_PI/2}" />
      <geometry>
        <mesh filename="package://lmtclam/model/stl/wrist_roll_link.STL" scale="${M_SCALE}" />
      </geometry>
      <material name="Black" />
    </visual>

    <collision>
      <origin xyz="0 0 0" rpy="0 ${M_PI/2} ${M_PI/2}" />
      <geometry>
        <mesh filename="package://lmtclam/model/stl/wrist_roll_link_simple.STL" scale="${M_SCALE}" />
      </geometry>
    </collision>

  </link>

  <gazebo reference="wrist_roll_link">
    <material>Gazebo/Black</material>
  </gazebo>

  <joint name="joint5" type="revolute">
    <parent link="wrist_roll_link"/>
    <child link="wrist_pitch_link"/>
    <origin xyz="0.0 0.0 0.0" rpy="0 0 0" oldxyz="0.0 0.0 0.0001" oldrpy="0 ${M_PI/2} 0" />
    <axis xyz="0 0 -1" />
    <limit effort="300" velocity="1" lower="-1.90" upper="1.70" />
    <dynamics damping="50" friction="1"/>
  </joint>

  <!-- WRIST PITCH LINK -->
  <link name="wrist_pitch_link">
    <inertial>
      <origin xyz="0 0 0"  />
      <mass value="1.0" />
      <inertia  ixx="1.0" ixy="0.0"  ixz="0.0"  iyy="100.0"  iyz="0.0"  izz="1.0" />
    </inertial>

    <visual>
      <origin xyz="0 0 ${0.0355/2}" rpy="${M_PI} ${M_PI} 0"/>
      <geometry>
        <!-- Center of mesh: Axis of Dynamixel, on surface (not on horn) -->
        <mesh filename="package://lmtclam/model/stl/MX28T.dae" scale="0.00000002555635319 0.00000002555635319 0.00000002555635319 "/>
      </geometry>
    </visual>
    <visual>
      <origin xyz="${0.0358 + 0.01 + 0.03275} 0 0" rpy="${M_PI/2} 0 ${M_PI/2}"/>
      <geometry>
        <mesh filename="package://lmtclam/model/stl/MX28T.dae" scale="0.00000002555635319 0.00000002555635319 0.00000002555635319 "/>
      </geometry>
    </visual>
    <collision>
      <!-- 0.012: Distance from MX28 axis to edge; Dynamixel outer dimensions: 0.0506x0.0356x0.041 (LxWxH) -->
      <origin xyz="${0.0506/2 - 0.012} 0 0" rpy="0 0 0"/>
      <geometry><box size="0.0506 .0356 0.041"/></geometry>
    </collision>
    <collision>
      <origin xyz="${0.0358 + 0.01 + 0.03275  - .0356/2}   -0.012 0" rpy="${M_PI/2} 0 ${M_PI/2}"/>
      <geometry><box size="0.0506 .0356 0.041"/></geometry>
    </collision>

  </link>

  <gazebo reference="wrist_pitch_link">
    <material>Gazebo/Black</material>
  </gazebo>

  <joint name="joint6" type="revolute">
    <parent link="wrist_pitch_link"/>
    <child link="gripper_roll_link"/>
    <!-- y should be 0.004, but if we set this to 0, FastIK works much faster -->
    <origin xyz="${0.0358 + 0.007 + 0.030 + 0.00275 + 0.00275} 0.0 0.0" rpy="0 0 0" oldxyz="0 0 0.080" oldrpy="${1.5*M_PI} -${.5*M_PI} 0" />
    <!-- Height of frame FR07-X101: 7mm from drawing -->
    <axis xyz="1 0 0" />
    <limit effort="300" velocity="1" lower="${-M_PI}" upper="${M_PI}" />
    <dynamics damping="50" friction="1"/>
  </joint>

  <!-- GRIPPER ROLL LINK -->
  <link name="gripper_roll_link">
  </link>

  <gazebo reference="gripper_roll_link">
    <material>Gazebo/Orange</material>
  </gazebo>

  <!-- Include Tools -->
  <xacro:include filename="$(find lmtclam)/model/tool_$(arg tool).xacro" />

 


  <!-- Transmissions for ROS Control -->
  <transmission name="tran1">
    <type>transmission_interface/SimpleTransmission</type>
    <joint name="joint0"/>
    <actuator name="motor1">
      <hardwareInterface>EffortJointInterface</hardwareInterface>
      <mechanicalReduction>1</mechanicalReduction>
    </actuator>
  </transmission>

  <transmission name="tran1">
    <type>transmission_interface/SimpleTransmission</type>
    <joint name="joint1"/>
    <actuator name="motor1">
      <hardwareInterface>EffortJointInterface</hardwareInterface>
      <mechanicalReduction>1</mechanicalReduction>
    </actuator>
  </transmission>

  <transmission name="tran1">
    <type>transmission_interface/SimpleTransmission</type>
    <joint name="joint2"/>
    <actuator name="motor1">
      <hardwareInterface>EffortJointInterface</hardwareInterface>
      <mechanicalReduction>1</mechanicalReduction>
    </actuator>
  </transmission>

  <transmission name="tran1">
    <type>transmission_interface/SimpleTransmission</type>
    <joint name="joint3"/>
    <actuator name="motor1">
      <hardwareInterface>EffortJointInterface</hardwareInterface>
      <mechanicalReduction>1</mechanicalReduction>
    </actuator>
  </transmission>

  <transmission name="tran1">
    <type>transmission_interface/SimpleTransmission</type>
    <joint name="joint4"/>
    <actuator name="motor1">
      <hardwareInterface>EffortJointInterface</hardwareInterface>
      <mechanicalReduction>1</mechanicalReduction>
    </actuator>
  </transmission>

  <transmission name="tran1">
    <type>transmission_interface/SimpleTransmission</type>
    <joint name="joint5"/>
    <actuator name="motor1">
      <hardwareInterface>EffortJointInterface</hardwareInterface>
      <mechanicalReduction>1</mechanicalReduction>
    </actuator>
  </transmission>

  <transmission name="tran1">
    <type>transmission_interface/SimpleTransmission</type>
    <joint name="joint6"/>
    <actuator name="motor1">
      <hardwareInterface>EffortJointInterface</hardwareInterface>
      <mechanicalReduction>1</mechanicalReduction>
    </actuator>
  </transmission>

  <transmission name="tran1">
    <type>transmission_interface/SimpleTransmission</type>
    <joint name="gripper_finger_joint"/>
    <actuator name="motor1">
      <hardwareInterface>EffortJointInterface</hardwareInterface>
      <mechanicalReduction>1</mechanicalReduction>
    </actuator>
  </transmission>

  <!-- ros_control plugin -->
  <gazebo>
    <plugin name="gazebo_ros_control" filename="libgazebo_ros_control.so">
      <robotNamespace>/clam</robotNamespace>
    </plugin>
  </gazebo>


</robot>
