<?xml version="1.0" ?>
<!-- =================================================================================== -->
<!-- |    This document was autogenerated by xacro from ../model/clam.xacro            | -->
<!-- |    EDITING THIS FILE BY HAND IS NOT RECOMMENDED                                 | -->
<!-- =================================================================================== -->
<!-- Robot Description format of CLAM arm
Dave Coleman - davetcoleman@gmail.com
10/23/13

Nicolas Alt, 2014-08-21

Documentation:

URDF
http://www.ros.org/wiki/urdf/XML

XARCO - Macro Language
http://www.ros.org/wiki/xacro

-->
<robot name="lmtclam" xmlns:xacro="http://www.ros.org/wiki/xacro">
  <!-- Include materials -->
  <material name="Black">
    <color rgba="0.0 0.0 0.0 1.0"/>
  </material>
  <material name="Blue">
    <color rgba="0.0 0.0 0.8 1.0"/>
  </material>
  <material name="Green">
    <color rgba="0.0 0.8 0.0 1.0"/>
  </material>
  <material name="Grey">
    <color rgba="0.2 0.2 0.2 1.0"/>
  </material>
  <material name="Orange">
    <color rgba="1.0 0.423529411765 0.0392156862745 1.0"/>
  </material>
  <material name="Brown">
    <color rgba="0.870588235294 0.811764705882 0.764705882353 1.0"/>
  </material>
  <material name="Red">
    <color rgba="0.8 0.0 0.0 1.0"/>
  </material>
  <material name="White">
    <color rgba="1.0 1.0 1.0 1.0"/>
  </material>
  <!-- Constants -->
  <!-- TABLETOP LINK -->
  <joint name="tabletop_joint" type="fixed">
    <origin rpy="-1.57079632679 -1.57079632679 0" xyz="0 0 0"/>
    <!-- Rotate the coordinate system:
         tabletop_link: plane spanned by x-y, z goes up
         arm_base_link: x along arm, y to front, x to left -->
    <parent link="tabletop_link"/>
    <child link="arm_base_link"/>
  </joint>
  <link name="tabletop_link">
    <inertial>
      <origin xyz="0 0 -0.017"/>
      <mass value="100.0"/>
      <inertia ixx="1.0" ixy="0.0" ixz="0.0" iyy="100.0" iyz="0.0" izz="1.0"/>
    </inertial>
    <!-- visual>
      <origin xyz=" 0 0 -0.017"  rpy="${.5*M_PI} 0 ${.5*M_PI}"/>
      <geometry>
        <mesh filename="package://lmt_clamarm/model/stl/tabletop_link.STL" scale="${M_SCALE}" />
      </geometry>
      <material name="Brown" />
    </visual -->
    <!-- collision>
      <origin xyz=" 0 0 -0.017"  rpy="${.5*M_PI} 0 ${.5*M_PI}"/>
      <geometry>
        <mesh filename="package://lmt_clamarm/model/stl/tabletop_link_simple.STL" scale="${M_SCALE}" />
      </geometry>
      </collision> -->
  </link>
  <gazebo reference="tabletop_link">
    <material>Gazebo/White</material>
  </gazebo>
  <!-- BASE LINK -->
  <link name="arm_base_link">
    <!--inertial>
        <origin xyz="0 0 0" />
        <mass value="1.0" />
        <inertia  ixx="1.0" ixy="0.0"  ixz="0.0"  iyy="100.0"  iyz="0.0"  izz="1.0" />
        </inertial-->
    <visual>
      <origin oldrpy="1.57079632679 0 0" rpy="0 0 -1.57079632679" xyz="0 0 0"/>
      <!-- rotate PI/2 -->
      <geometry>
        <mesh filename="package://lmt_clamarm/model/stl/base_link.STL" scale="0.001 0.001 0.001"/>
      </geometry>
      <material name="Grey"/>
    </visual>
    <collision>
      <origin oldrpy="1.57079632679 0 0" rpy="0 0 -1.57079632679" xyz="0 0 0"/>
      <!-- rotate PI/2 -->
      <geometry>
        <mesh filename="package://lmt_clamarm/model/stl/base_link_simple.STL" scale="0.001 0.001 0.001"/>
      </geometry>
    </collision>
  </link>
  <gazebo reference="arm_base_link">
    <material>Gazebo/Grey</material>
  </gazebo>
  <joint name="joint0" type="revolute">
    <parent link="arm_base_link"/>
    <child link="shoulder_pan_link"/>
    <origin rpy="0 0 0" xyz="0.05 0 0"/>
    <axis xyz="1 0 0"/>
    <limit effort="300" lower="-3.14159265359" upper="3.14159265359" velocity="1"/>
    <dynamics damping="50" friction="1"/>
  </joint>
  <!-- SHOULDER PAN LINK -->
  <link name="shoulder_pan_link">
    <inertial>
      <origin xyz="0 0 0"/>
      <mass value="1.0"/>
      <inertia ixx="1.0" ixy="0.0" ixz="0.0" iyy="100.0" iyz="0.0" izz="1.0"/>
    </inertial>
    <visual>
      <origin oldrpy="0 0 1.57079632679" rpy="1.57079632679 1.57079632679 0" xyz="0 0 0"/>
      <geometry>
        <mesh filename="package://lmt_clamarm/model/stl/shoulder_pan_link.STL" scale="0.001 0.001 0.001"/>
      </geometry>
      <material name="Orange"/>
    </visual>
    <collision>
      <origin oldrpy="0 0 1.57079632679" rpy="1.57079632679 1.57079632679 0" xyz="0 0 0"/>
      <geometry>
        <mesh filename="package://lmt_clamarm/model/stl/shoulder_pan_link_simple.STL" scale="0.001 0.001 0.001"/>
      </geometry>
    </collision>
  </link>
  <gazebo reference="shoulder_pan_link">
    <material>Gazebo/Orange</material>
  </gazebo>
  <joint name="joint1" type="revolute">
    <parent link="shoulder_pan_link"/>
    <child link="shoulder_pitch_link"/>
    <!-- todo: why 0.0021?? -->
    <origin oldrpy="-1.57079632679 0 1.57079632679" oldxyz="-0.041 0.0021 0.0" rpy="0 0 0" xyz="0.041 0.0 0.0"/>
    <axis xyz="0 0 -1"/>
    <!-- modified! -->
    <limit effort="300" lower="-1.8" upper="1.25" velocity="1"/>
    <dynamics damping="50" friction="1"/>
  </joint>
  <!-- SHOULDER PITCH LINK -->
  <link name="shoulder_pitch_link">
    <inertial>
      <origin xyz="-0.002 0 -0.000"/>
      <mass value="1.0"/>
      <inertia ixx="1.0" ixy="0.0" ixz="0.0" iyy="100.0" iyz="0.0" izz="1.0"/>
    </inertial>
    <visual>
      <origin oldrpy="1.57079632679 3.14159265359 1.57079632679" rpy="0 0 1.57079632679" xyz="-0.002 0 -0.000"/>
      <geometry>
        <mesh filename="package://lmt_clamarm/model/stl/shoulder_pitch_link.STL" scale="0.001 0.001 0.001"/>
      </geometry>
      <material name="Grey"/>
    </visual>
    <collision>
      <origin rpy="0 0 1.57079632679" xyz="-0.002 0 -0.000"/>
      <geometry>
        <mesh filename="package://lmt_clamarm/model/stl/shoulder_pitch_link_simple.STL" scale="0.001 0.001 0.001"/>
      </geometry>
    </collision>
  </link>
  <gazebo reference="shoulder_pitch_link">
    <material>Gazebo/Grey</material>
  </gazebo>
  <joint name="joint2" type="revolute">
    <parent link="shoulder_pitch_link"/>
    <child link="elbow_roll_link"/>
    <origin oldrpy="3.14159265359 1.57079632679 0" oldxyz="-0.002 0 0.1206" rpy="0 0 0" xyz="0.12 0.0 0"/>
    <axis xyz="1 0 0"/>
    <limit effort="300" lower="-3.14159265359" upper="3.14159265359" velocity="1"/>
    <dynamics damping="50" friction="1"/>
  </joint>
  <!-- ELBOW ROLL LINK -->
  <link name="elbow_roll_link">
    <inertial>
      <origin xyz="-0.035 0.0 0.0"/>
      <mass value="1.0"/>
      <inertia ixx="1.0" ixy="0.0" ixz="0.0" iyy="100.0" iyz="0.0" izz="1.0"/>
    </inertial>
    <visual>
      <origin oldrpy="3.14159265359 1.57079632679 1.57079632679" rpy="1.57079632679 1.57079632679 3.14159265359" xyz="0.035 0.0 0.0"/>
      <geometry>
        <mesh filename="package://lmt_clamarm/model/stl/elbow_roll_link.STL" scale="0.001 0.001 0.001"/>
      </geometry>
      <material name="Black"/>
    </visual>
    <collision>
      <origin rpy="1.57079632679 1.57079632679 3.14159265359" xyz="0.035 0.0 0.0"/>
      <geometry>
        <mesh filename="package://lmt_clamarm/model/stl/elbow_roll_link_simple.STL" scale="0.001 0.001 0.001"/>
      </geometry>
    </collision>
  </link>
  <gazebo reference="elbow_roll_link">
    <material>Gazebo/Black</material>
  </gazebo>
  <joint name="joint3" type="revolute">
    <parent link="elbow_roll_link"/>
    <child link="elbow_pitch_link"/>
    <origin oldrpy="0.0 1.57079632679 0" oldxyz="-0.035 0 0.0" rpy="0.0 0 0" xyz="0.035 0 0.0"/>
    <axis xyz="0 0 1"/>
    <limit effort="300" lower="-1.59" upper="1.93" velocity="1"/>
    <dynamics damping="50" friction="1"/>
  </joint>
  <!-- ELBOW PITCH LINK -->
  <link name="elbow_pitch_link">
    <inertial>
      <origin xyz="0.0 0 0"/>
      <mass value="1.0"/>
      <inertia ixx="1.0" ixy="0.0" ixz="0.0" iyy="100.0" iyz="0.0" izz="1.0"/>
    </inertial>
    <visual>
      <origin oldrpy="1.57079632679 0 4.71238898038" rpy="3.14159265359 0 -1.57079632679 " xyz="0.0 0 0"/>
      <geometry>
        <mesh filename="package://lmt_clamarm/model/stl/elbow_pitch_link.STL" scale="0.001 0.001 0.001"/>
      </geometry>
      <material name="Orange"/>
    </visual>
    <collision>
      <origin rpy="3.14159265359 0 -1.57079632679 " xyz="0.0 0 0"/>
      <geometry>
        <mesh filename="package://lmt_clamarm/model/stl/elbow_pitch_link_simple.STL" scale="0.001 0.001 0.001"/>
      </geometry>
    </collision>
  </link>
  <gazebo reference="elbow_pitch_link">
    <material>Gazebo/Orange</material>
  </gazebo>
  <joint name="joint4" type="revolute">
    <parent link="elbow_pitch_link"/>
    <child link="wrist_roll_link"/>
    <origin oldrpy="0 1.57079632679 3.14159265359" oldxyz="0.0 0.0081 -.248" rpy="0 0 0" xyz="0.248 0.008 0"/>
    <!-- Includes Bracket height: 30mm (from drawing) -->
    <axis xyz="1 0 0"/>
    <limit effort="300" lower="-3.14159265359" upper="3.14159265359" velocity="1"/>
    <dynamics damping="50" friction="1"/>
  </joint>
  <!-- WRIST ROLL LINK -->
  <link name="wrist_roll_link">
    <inertial>
      <origin xyz="0 0 0"/>
      <mass value="1.0"/>
      <inertia ixx="1.0" ixy="0.0" ixz="0.0" iyy="100.0" iyz="0.0" izz="1.0"/>
    </inertial>
    <visual>
      <origin rpy="0 1.57079632679 1.57079632679" xyz="0 0 0"/>
      <geometry>
        <mesh filename="package://lmt_clamarm/model/stl/wrist_roll_link.STL" scale="0.001 0.001 0.001"/>
      </geometry>
      <material name="Black"/>
    </visual>
    <collision>
      <origin rpy="0 1.57079632679 1.57079632679" xyz="0 0 0"/>
      <geometry>
        <mesh filename="package://lmt_clamarm/model/stl/wrist_roll_link_simple.STL" scale="0.001 0.001 0.001"/>
      </geometry>
    </collision>
  </link>
  <gazebo reference="wrist_roll_link">
    <material>Gazebo/Black</material>
  </gazebo>
  <joint name="joint5" type="revolute">
    <parent link="wrist_roll_link"/>
    <child link="wrist_pitch_link"/>
    <origin oldrpy="0 1.57079632679 0" oldxyz="0.0 0.0 0.0001" rpy="0 0 0" xyz="0.0 0.0 0.0"/>
    <axis xyz="0 0 -1"/>
    <limit effort="300" lower="-1.90" upper="1.70" velocity="1"/>
    <dynamics damping="50" friction="1"/>
  </joint>
  <!-- WRIST PITCH LINK -->
  <link name="wrist_pitch_link">
    <inertial>
      <origin xyz="0 0 0"/>
      <mass value="1.0"/>
      <inertia ixx="1.0" ixy="0.0" ixz="0.0" iyy="100.0" iyz="0.0" izz="1.0"/>
    </inertial>
    <visual>
      <origin oldrpy="3.14159265359 -1.57079632679 0" rpy="0 0 0" xyz="0 0 0"/>
      <geometry>
        <!-- Todo: Update Mesh with MX28 -->
        <mesh filename="package://lmt_clamarm/model/stl/wrist_pitch_link.STL" scale="0.001 0.001 0.001"/>
      </geometry>
      <material name="Grey"/>
    </visual>
    <collision>
      <origin oldrpy="3.14159265359 -1.57079632679 0" rpy="0 0 0" xyz="0 0 0"/>
      <geometry>
        <mesh filename="package://lmt_clamarm/model/stl/wrist_pitch_link_simple.STL" scale="0.001 0.001 0.001"/>
      </geometry>
    </collision>
  </link>
  <gazebo reference="wrist_pitch_link">
    <material>Gazebo/Grey</material>
  </gazebo>
  <joint name="joint6" type="revolute">
    <parent link="wrist_pitch_link"/>
    <child link="gripper_roll_link"/>
    <!-- y should be 0.004, but if we set this to 0, FastIK works much faster -->
    <origin oldrpy="4.71238898038 -1.57079632679 0" oldxyz="0 0 0.080" rpy="0 0 0" xyz="0.0783 0.0 0.0"/>
    <!-- Height of frame FR07-X101: 7mm from drawing -->
    <axis xyz="1 0 0"/>
    <limit effort="300" lower="-3.14159265359" upper="3.14159265359" velocity="1"/>
    <dynamics damping="50" friction="1"/>
  </joint>
  <!-- GRIPPER ROLL LINK -->
  <link name="gripper_roll_link">
    <inertial>
      <origin xyz="0 0 0"/>
      <mass value="1.0"/>
      <inertia ixx="1.0" ixy="0.0" ixz="0.0" iyy="100.0" iyz="0.0" izz="1.0"/>
    </inertial>
    <visual>
      <origin rpy="0 0 0" xyz="0 0 0"/>
      <geometry>
        <mesh filename="package://lmt_clamarm/model/stl/gripper_roll_link.STL" scale="0.001 0.001 0.001"/>
      </geometry>
      <material name="Orange"/>
    </visual>
    <collision>
      <origin rpy="0 0 0" xyz="0 0 0"/>
      <geometry>
        <mesh filename="package://lmt_clamarm/model/stl/gripper_roll_link.STL" scale="0.001 0.001 0.001"/>
      </geometry>
    </collision>
  </link>
  <gazebo reference="gripper_roll_link">
    <material>Gazebo/Orange</material>
  </gazebo>
  <joint name="gripper_finger_joint" type="revolute">
    <parent link="gripper_roll_link"/>
    <child link="gripper_finger_link"/>
    <origin rpy="3.26725635973 1.57079632679 0.60353485534" xyz="0.026 .017 0"/>
    <axis xyz="1 0 0"/>
    <limit effort="300" lower="-0.925024503557" upper="0.0" velocity="1"/>
    <dynamics damping="50" friction="1"/>
  </joint>
  <!-- LEFT GRIPPER AFT LINK -->
  <link name="gripper_finger_link">
    <inertial>
      <origin xyz="0 0 0"/>
      <mass value="1.0"/>
      <inertia ixx="1.0" ixy="0.0" ixz="0.0" iyy="100.0" iyz="0.0" izz="1.0"/>
    </inertial>
    <visual>
      <origin rpy="0 0 3.14159265359" xyz="0 0 0"/>
      <geometry>
        <mesh filename="package://lmt_clamarm/model/stl/l_gripper_aft_link.STL" scale="1 1 1"/>
      </geometry>
      <material name="Grey"/>
    </visual>
  </link>
  <gazebo reference="l_gripper_aft_link">
    <material>Gazebo/Grey</material>
  </gazebo>
  <joint name="r_gripper_aft_joint" type="revolute">
    <parent link="gripper_roll_link"/>
    <child link="r_gripper_aft_link"/>
    <origin rpy="4.22544211908 1.57079632679 0.60353485534" xyz="0.026 -0.011  0"/>
    <axis xyz="1 0 0"/>
    <limit effort="300" lower="-3.14" upper="3.14" velocity="1"/>
    <mimic joint="gripper_finger_joint" multiplier="-1.0" offset="0.0"/>
    <dynamics damping="50" friction="1"/>
  </joint>
  <!-- RIGHT GRIPPER AFT LINK -->
  <link name="r_gripper_aft_link">
    <inertial>
      <origin xyz="0 0 0"/>
      <mass value="1.0"/>
      <inertia ixx="1.0" ixy="0.0" ixz="0.0" iyy="100.0" iyz="0.0" izz="1.0"/>
    </inertial>
    <visual>
      <origin rpy="0 0 3.14159265359" xyz="0 0 0"/>
      <geometry>
        <mesh filename="package://lmt_clamarm/model/stl/r_gripper_aft_link.STL" scale="1 1 1"/>
      </geometry>
      <material name="Grey"/>
    </visual>
  </link>
  <gazebo reference="r_gripper_aft_link">
    <material>Gazebo/Grey</material>
  </gazebo>
  <joint name="l_gripper_fwd_joint" type="revolute">
    <parent link="gripper_roll_link"/>
    <child link="l_gripper_fwd_link"/>
    <origin rpy="3.26725635973 1.57079632679 3.74512750893" xyz="0.05 0.008 0.007"/>
    <axis xyz="1 0 0"/>
    <limit effort="300" lower="0" upper="1.57" velocity="1"/>
    <mimic joint="gripper_finger_joint" multiplier="1.0" offset="0.0"/>
    <dynamics damping="50" friction="1"/>
  </joint>
  <!-- LEFT GRIPPER FWD LINK -->
  <link name="l_gripper_fwd_link">
    <inertial>
      <origin xyz="0 0 0"/>
      <mass value="1.0"/>
      <inertia ixx="1.0" ixy="0.0" ixz="0.0" iyy="100.0" iyz="0.0" izz="1.0"/>
    </inertial>
    <visual>
      <origin rpy="0 0 3.14159265359" xyz="0 0 0"/>
      <geometry>
        <mesh filename="package://lmt_clamarm/model/stl/l_gripper_fwd_link.STL" scale="1 1 1"/>
      </geometry>
      <material name="Grey"/>
    </visual>
  </link>
  <gazebo reference="l_gripper_fwd_link">
    <material>Gazebo/Grey</material>
  </gazebo>
  <joint name="r_gripper_fwd_joint" type="revolute">
    <parent link="gripper_roll_link"/>
    <child link="r_gripper_fwd_link"/>
    <origin rpy="3.01592894745 1.57079632679 2.53805779825" xyz="0.05 -0.0014 0.007"/>
    <axis xyz="1 0 0"/>
    <limit effort="300" lower="-1.57" upper="0" velocity="1"/>
    <mimic joint="gripper_finger_joint" multiplier="-1.0" offset="0.0"/>
    <dynamics damping="50" friction="1"/>
  </joint>
  <!-- RIGHT GRIPPER FWD LINK -->
  <link name="r_gripper_fwd_link">
    <inertial>
      <origin xyz="0 0 0"/>
      <mass value="1.0"/>
      <inertia ixx="1.0" ixy="0.0" ixz="0.0" iyy="100.0" iyz="0.0" izz="1.0"/>
    </inertial>
    <visual>
      <origin rpy="0 0 3.14159265359" xyz="0 0 0"/>
      <geometry>
        <mesh filename="package://lmt_clamarm/model/stl/r_gripper_fwd_link.STL" scale="1 1 1"/>
      </geometry>
      <material name="Grey"/>
    </visual>
  </link>
  <gazebo reference="r_gripper_fwd_link">
    <material>Gazebo/Grey</material>
  </gazebo>
  <joint name="gripper_finger_pincher_joint" type="revolute">
    <parent link="gripper_finger_link"/>
    <child link="l_gripper_pincher_link"/>
    <origin rpy="2.55812908465 0 0" xyz="-0.0032 0 -0.0508"/>
    <axis xyz="1 0 0"/>
    <limit effort="300" lower="-1.57" upper="1.57" velocity="1"/>
    <mimic joint="gripper_finger_joint" multiplier="-1.0" offset="0.0"/>
    <dynamics damping="50" friction="1"/>
  </joint>
  <!-- LEFT GRIPPER PINCHER -->
  <link name="l_gripper_pincher_link">
    <inertial>
      <origin xyz="0 0 0"/>
      <mass value="1.0"/>
      <inertia ixx="1.0" ixy="0.0" ixz="0.0" iyy="100.0" iyz="0.0" izz="1.0"/>
    </inertial>
    <visual>
      <origin rpy="0 0 3.14159265359" xyz="0 0 0"/>
      <geometry>
        <mesh filename="package://lmt_clamarm/model/stl/l_gripper_pincher.STL" scale="1 1 1"/>
      </geometry>
      <material name="Black"/>
    </visual>
  </link>
  <gazebo reference="l_gripper_pincher_link">
    <material>Gazebo/Black</material>
  </gazebo>
  <joint name="r_gripper_aft_pincher_joint" type="revolute">
    <parent link="r_gripper_aft_link"/>
    <child link="r_gripper_pincher_link"/>
    <origin rpy="-0.583463568942 3.14159265359 0" xyz="0 0 -0.0508"/>
    <axis xyz="1 0 0"/>
    <limit effort="300" lower="0" upper="1.57" velocity="1"/>
    <mimic joint="gripper_finger_joint" multiplier="-1.0" offset="0.0"/>
    <dynamics damping="50" friction="1"/>
  </joint>
  <!-- RIGHT GRIPPER PINCHER -->
  <link name="r_gripper_pincher_link">
    <inertial>
      <origin xyz="0 0 0"/>
      <mass value="1.0"/>
      <inertia ixx="1.0" ixy="0.0" ixz="0.0" iyy="100.0" iyz="0.0" izz="1.0"/>
    </inertial>
    <visual>
      <origin rpy="0 0 3.14159265359" xyz="0 0 0"/>
      <geometry>
        <mesh filename="package://lmt_clamarm/model/stl/r_gripper_pincher.STL" scale="1 1 1"/>
      </geometry>
      <material name="Black"/>
    </visual>
  </link>
  <gazebo reference="r_gripper_pincher_link">
    <material>Gazebo/Black</material>
  </gazebo>
  <!-- Transmissions for ROS Control -->
  <transmission name="tran1">
    <type>transmission_interface/SimpleTransmission</type>
    <joint name="joint0"/>
    <actuator name="motor1">
      <hardwareInterface>EffortJointInterface</hardwareInterface>
      <mechanicalReduction>1</mechanicalReduction>
    </actuator>
  </transmission>
  <transmission name="tran1">
    <type>transmission_interface/SimpleTransmission</type>
    <joint name="joint1"/>
    <actuator name="motor1">
      <hardwareInterface>EffortJointInterface</hardwareInterface>
      <mechanicalReduction>1</mechanicalReduction>
    </actuator>
  </transmission>
  <transmission name="tran1">
    <type>transmission_interface/SimpleTransmission</type>
    <joint name="joint2"/>
    <actuator name="motor1">
      <hardwareInterface>EffortJointInterface</hardwareInterface>
      <mechanicalReduction>1</mechanicalReduction>
    </actuator>
  </transmission>
  <transmission name="tran1">
    <type>transmission_interface/SimpleTransmission</type>
    <joint name="joint3"/>
    <actuator name="motor1">
      <hardwareInterface>EffortJointInterface</hardwareInterface>
      <mechanicalReduction>1</mechanicalReduction>
    </actuator>
  </transmission>
  <transmission name="tran1">
    <type>transmission_interface/SimpleTransmission</type>
    <joint name="joint4"/>
    <actuator name="motor1">
      <hardwareInterface>EffortJointInterface</hardwareInterface>
      <mechanicalReduction>1</mechanicalReduction>
    </actuator>
  </transmission>
  <transmission name="tran1">
    <type>transmission_interface/SimpleTransmission</type>
    <joint name="joint5"/>
    <actuator name="motor1">
      <hardwareInterface>EffortJointInterface</hardwareInterface>
      <mechanicalReduction>1</mechanicalReduction>
    </actuator>
  </transmission>
  <transmission name="tran1">
    <type>transmission_interface/SimpleTransmission</type>
    <joint name="joint6"/>
    <actuator name="motor1">
      <hardwareInterface>EffortJointInterface</hardwareInterface>
      <mechanicalReduction>1</mechanicalReduction>
    </actuator>
  </transmission>
  <transmission name="tran1">
    <type>transmission_interface/SimpleTransmission</type>
    <joint name="gripper_finger_joint"/>
    <actuator name="motor1">
      <hardwareInterface>EffortJointInterface</hardwareInterface>
      <mechanicalReduction>1</mechanicalReduction>
    </actuator>
  </transmission>
  <!-- ros_control plugin -->
  <gazebo>
    <plugin filename="libgazebo_ros_control.so" name="gazebo_ros_control">
      <robotNamespace>/clam</robotNamespace>
    </plugin>
  </gazebo>
  <!-- FAKE CAMERA CALIBRATION POINT AT GRIPPER TIP -->
  <!--joint name="gripper_fake_tip_joint" type="fixed">
    <origin xyz="0.1785 0.0 0.0" rpy="0 0 0" />
    <parent link="gripper_roll_link"/>
    <child link="gripper_fake_tip_link" />
  </joint>

  <link name="gripper_fake_tip_link" >

    <inertial>
      <origin xyz="0 0 0" />
      <mass value="0.01" />
      <inertia  ixx="1.0" ixy="0.0"  ixz="0.0"  iyy="100.0"  iyz="0.0"  izz="1.0" />
    </inertial>

    <visual>
      <origin xyz="0 0 0" rpy="0 0 0" />
      <geometry>
        <sphere radius=".001"/>
      </geometry>
    </visual>

    <collision>
      <origin xyz="-0.1 0 0" rpy="0 0 0" />
      <geometry>
        <sphere radius=".001"/>
      </geometry>
    </collision>

  </link>

  <gazebo reference="gripper_fake_tip_link">
    <material>Gazebo/Grey</material>
  </gazebo-->
</robot>

