<?xml version="1.0" ?>
<!-- =================================================================================== -->
<!-- |    This document was autogenerated by xacro from ../model/clam.xacro            | -->
<!-- |    EDITING THIS FILE BY HAND IS NOT RECOMMENDED                                 | -->
<!-- =================================================================================== -->
<!-- Robot Description format of CLAM arm
Dave Coleman - davetcoleman@gmail.com, 10/23/13

Nicolas Alt, 2014-08-21

Documentation:

URDF
http://www.ros.org/wiki/urdf/XML

XARCO - Macro Language
http://www.ros.org/wiki/xacro

-->
<robot name="lmtclam" xmlns:xacro="http://www.ros.org/wiki/xacro">
  <!-- Include URDFs -->
  <material name="Black">
    <color rgba="0.0 0.0 0.0 1.0"/>
  </material>
  <material name="Blue">
    <color rgba="0.0 0.0 0.8 1.0"/>
  </material>
  <material name="Green">
    <color rgba="0.0 0.8 0.0 1.0"/>
  </material>
  <material name="Grey">
    <color rgba="0.2 0.2 0.2 1.0"/>
  </material>
  <material name="Orange">
    <color rgba="1.0 0.423529411765 0.0392156862745 1.0"/>
  </material>
  <material name="Brown">
    <color rgba="0.870588235294 0.811764705882 0.764705882353 1.0"/>
  </material>
  <material name="Red">
    <color rgba="0.8 0.0 0.0 1.0"/>
  </material>
  <material name="White">
    <color rgba="1.0 1.0 1.0 1.0"/>
  </material>
  <!-- Constants -->
  <!-- TABLETOP LINK -->
  <joint name="tabletop_joint" type="fixed">
    <origin rpy="-1.57079632679 -1.57079632679 0" xyz="0 0 0"/>
    <!-- Rotate the coordinate system:
         tabletop_link: plane spanned by x-y, z goes up
         arm_base_link: x along arm, y to front, x to left -->
    <parent link="tabletop_link"/>
    <child link="arm_base_link"/>
  </joint>
  <link name="tabletop_link">
    <inertial>
      <origin xyz="0 0 -0.017"/>
      <mass value="100.0"/>
      <inertia ixx="1.0" ixy="0.0" ixz="0.0" iyy="100.0" iyz="0.0" izz="1.0"/>
    </inertial>
    <!-- visual>
      <origin xyz=" 0 0 -0.017"  rpy="${.5*M_PI} 0 ${.5*M_PI}"/>
      <geometry>
        <mesh filename="package://lmtclam/model/stl/tabletop_link.STL" scale="${M_SCALE}" />
      </geometry>
      <material name="Brown" />
    </visual -->
    <!-- collision>
      <origin xyz=" 0 0 -0.017"  rpy="${.5*M_PI} 0 ${.5*M_PI}"/>
      <geometry>
        <mesh filename="package://lmtclam/model/stl/tabletop_link_simple.STL" scale="${M_SCALE}" />
      </geometry>
      </collision> -->
  </link>
  <gazebo reference="tabletop_link">
    <material>Gazebo/White</material>
  </gazebo>
  <!-- BASE LINK -->
  <link name="arm_base_link">
    <!--inertial>
        <origin xyz="0 0 0" />
        <mass value="1.0" />
        <inertia  ixx="1.0" ixy="0.0"  ixz="0.0"  iyy="100.0"  iyz="0.0"  izz="1.0" />
        </inertial-->
    <visual>
      <origin oldrpy="1.57079632679 0 0" rpy="0 0 -1.57079632679" xyz="0 0 0"/>
      <!-- rotate PI/2 -->
      <geometry>
        <mesh filename="package://lmtclam/model/stl/base_link.STL" scale="0.001 0.001 0.001"/>
      </geometry>
      <material name="Grey"/>
    </visual>
    <collision>
      <origin oldrpy="1.57079632679 0 0" rpy="0 0 -1.57079632679" xyz="0 0 0"/>
      <!-- rotate PI/2 -->
      <geometry>
        <mesh filename="package://lmtclam/model/stl/base_link_simple.STL" scale="0.001 0.001 0.001"/>
      </geometry>
    </collision>
  </link>
  <gazebo reference="arm_base_link">
    <material>Gazebo/Grey</material>
  </gazebo>
  <joint name="joint0" type="revolute">
    <parent link="arm_base_link"/>
    <child link="shoulder_pan_link"/>
    <origin rpy="0 0 0" xyz="0.05 0 0"/>
    <axis xyz="1 0 0"/>
    <limit effort="300" lower="-3.14159265359" upper="3.14159265359" velocity="1"/>
    <dynamics damping="50" friction="1"/>
  </joint>
  <!-- SHOULDER PAN LINK -->
  <link name="shoulder_pan_link">
    <inertial>
      <origin xyz="0 0 0"/>
      <mass value="1.0"/>
      <inertia ixx="1.0" ixy="0.0" ixz="0.0" iyy="100.0" iyz="0.0" izz="1.0"/>
    </inertial>
    <visual>
      <origin oldrpy="0 0 1.57079632679" rpy="1.57079632679 1.57079632679 0" xyz="0 0 0"/>
      <geometry>
        <mesh filename="package://lmtclam/model/stl/shoulder_pan_link.STL" scale="0.001 0.001 0.001"/>
      </geometry>
      <material name="Orange"/>
    </visual>
    <collision>
      <origin oldrpy="0 0 1.57079632679" rpy="1.57079632679 1.57079632679 0" xyz="0 0 0"/>
      <geometry>
        <mesh filename="package://lmtclam/model/stl/shoulder_pan_link_simple.STL" scale="0.001 0.001 0.001"/>
      </geometry>
    </collision>
  </link>
  <gazebo reference="shoulder_pan_link">
    <material>Gazebo/Orange</material>
  </gazebo>
  <joint name="joint1" type="revolute">
    <parent link="shoulder_pan_link"/>
    <child link="shoulder_pitch_link"/>
    <!-- todo: why 0.0021?? -->
    <origin oldrpy="-1.57079632679 0 1.57079632679" oldxyz="-0.041 0.0021 0.0" rpy="0 0 0" xyz="0.041 0.0 0.0"/>
    <axis xyz="0 0 -1"/>
    <!-- modified! -->
    <limit effort="300" lower="-1.8" upper="1.25" velocity="1"/>
    <dynamics damping="50" friction="1"/>
  </joint>
  <!-- SHOULDER PITCH LINK -->
  <link name="shoulder_pitch_link">
    <inertial>
      <origin xyz="-0.002 0 -0.000"/>
      <mass value="1.0"/>
      <inertia ixx="1.0" ixy="0.0" ixz="0.0" iyy="100.0" iyz="0.0" izz="1.0"/>
    </inertial>
    <visual>
      <origin oldrpy="1.57079632679 3.14159265359 1.57079632679" rpy="0 0 1.57079632679" xyz="-0.002 0 -0.000"/>
      <geometry>
        <mesh filename="package://lmtclam/model/stl/shoulder_pitch_link.STL" scale="0.001 0.001 0.001"/>
      </geometry>
      <material name="Grey"/>
    </visual>
    <collision>
      <origin rpy="0 0 1.57079632679" xyz="-0.002 0 -0.000"/>
      <geometry>
        <mesh filename="package://lmtclam/model/stl/shoulder_pitch_link_simple.STL" scale="0.001 0.001 0.001"/>
      </geometry>
    </collision>
  </link>
  <gazebo reference="shoulder_pitch_link">
    <material>Gazebo/Grey</material>
  </gazebo>
  <joint name="joint2" type="revolute">
    <parent link="shoulder_pitch_link"/>
    <child link="elbow_roll_link"/>
    <origin oldrpy="3.14159265359 1.57079632679 0" oldxyz="-0.002 0 0.1206" rpy="0 0 0" xyz="0.12 0.0 0"/>
    <axis xyz="1 0 0"/>
    <limit effort="300" lower="-3.14159265359" upper="3.14159265359" velocity="1"/>
    <dynamics damping="50" friction="1"/>
  </joint>
  <!-- ELBOW ROLL LINK -->
  <link name="elbow_roll_link">
    <inertial>
      <origin xyz="-0.035 0.0 0.0"/>
      <mass value="1.0"/>
      <inertia ixx="1.0" ixy="0.0" ixz="0.0" iyy="100.0" iyz="0.0" izz="1.0"/>
    </inertial>
    <visual>
      <origin oldrpy="3.14159265359 1.57079632679 1.57079632679" rpy="1.57079632679 1.57079632679 3.14159265359" xyz="0.035 0.0 0.0"/>
      <geometry>
        <mesh filename="package://lmtclam/model/stl/elbow_roll_link.STL" scale="0.001 0.001 0.001"/>
      </geometry>
      <material name="Black"/>
    </visual>
    <collision>
      <origin rpy="1.57079632679 1.57079632679 3.14159265359" xyz="0.035 0.0 0.0"/>
      <geometry>
        <mesh filename="package://lmtclam/model/stl/elbow_roll_link_simple.STL" scale="0.001 0.001 0.001"/>
      </geometry>
    </collision>
  </link>
  <gazebo reference="elbow_roll_link">
    <material>Gazebo/Black</material>
  </gazebo>
  <joint name="joint3" type="revolute">
    <parent link="elbow_roll_link"/>
    <child link="elbow_pitch_link"/>
    <origin oldrpy="0.0 1.57079632679 0" oldxyz="-0.035 0 0.0" rpy="0.0 0 0" xyz="0.035 0 0.0"/>
    <axis xyz="0 0 1"/>
    <limit effort="300" lower="-1.59" upper="1.93" velocity="1"/>
    <dynamics damping="50" friction="1"/>
  </joint>
  <!-- ELBOW PITCH LINK -->
  <link name="elbow_pitch_link">
    <inertial>
      <origin xyz="0.0 0 0"/>
      <mass value="1.0"/>
      <inertia ixx="1.0" ixy="0.0" ixz="0.0" iyy="100.0" iyz="0.0" izz="1.0"/>
    </inertial>
    <visual>
      <origin oldrpy="1.57079632679 0 4.71238898038" rpy="3.14159265359 0 -1.57079632679 " xyz="0.0 0 0"/>
      <geometry>
        <mesh filename="package://lmtclam/model/stl/elbow_pitch_link.STL" scale="0.001 0.001 0.001"/>
      </geometry>
      <material name="Orange"/>
    </visual>
    <collision>
      <origin rpy="3.14159265359 0 -1.57079632679 " xyz="0.0 0 0"/>
      <geometry>
        <mesh filename="package://lmtclam/model/stl/elbow_pitch_link_simple.STL" scale="0.001 0.001 0.001"/>
      </geometry>
    </collision>
  </link>
  <gazebo reference="elbow_pitch_link">
    <material>Gazebo/Orange</material>
  </gazebo>
  <joint name="joint4" type="revolute">
    <parent link="elbow_pitch_link"/>
    <child link="wrist_roll_link"/>
    <origin oldrpy="0 1.57079632679 3.14159265359" oldxyz="0.0 0.0081 -.248" rpy="0 0 0" xyz="0.248 0.008 0"/>
    <!-- Includes Bracket height: 30mm (from drawing) -->
    <axis xyz="1 0 0"/>
    <limit effort="300" lower="-3.14159265359" upper="3.14159265359" velocity="1"/>
    <dynamics damping="50" friction="1"/>
  </joint>
  <!-- WRIST ROLL LINK -->
  <link name="wrist_roll_link">
    <inertial>
      <origin xyz="0 0 0"/>
      <mass value="1.0"/>
      <inertia ixx="1.0" ixy="0.0" ixz="0.0" iyy="100.0" iyz="0.0" izz="1.0"/>
    </inertial>
    <visual>
      <origin rpy="0 1.57079632679 1.57079632679" xyz="0 0 0"/>
      <geometry>
        <mesh filename="package://lmtclam/model/stl/wrist_roll_link.STL" scale="0.001 0.001 0.001"/>
      </geometry>
      <material name="Black"/>
    </visual>
    <collision>
      <origin rpy="0 1.57079632679 1.57079632679" xyz="0 0 0"/>
      <geometry>
        <mesh filename="package://lmtclam/model/stl/wrist_roll_link_simple.STL" scale="0.001 0.001 0.001"/>
      </geometry>
    </collision>
  </link>
  <gazebo reference="wrist_roll_link">
    <material>Gazebo/Black</material>
  </gazebo>
  <joint name="joint5" type="revolute">
    <parent link="wrist_roll_link"/>
    <child link="wrist_pitch_link"/>
    <origin oldrpy="0 1.57079632679 0" oldxyz="0.0 0.0 0.0001" rpy="0 0 0" xyz="0.0 0.0 0.0"/>
    <axis xyz="0 0 -1"/>
    <limit effort="300" lower="-1.90" upper="1.70" velocity="1"/>
    <dynamics damping="50" friction="1"/>
  </joint>
  <!-- WRIST PITCH LINK -->
  <link name="wrist_pitch_link">
    <inertial>
      <origin xyz="0 0 0"/>
      <mass value="1.0"/>
      <inertia ixx="1.0" ixy="0.0" ixz="0.0" iyy="100.0" iyz="0.0" izz="1.0"/>
    </inertial>
    <visual>
      <origin rpy="3.14159265359 3.14159265359 0" xyz="0 0 0.01775"/>
      <geometry>
        <!-- Center of mesh: Axis of Dynamixel, on surface (not on horn) -->
        <mesh filename="package://lmtclam/model/stl/MX28T.dae" scale="0.00000002555635319 0.00000002555635319 0.00000002555635319 "/>
      </geometry>
    </visual>
    <visual>
      <origin rpy="1.57079632679 0 1.57079632679" xyz="0.07855 0 0"/>
      <geometry>
        <mesh filename="package://lmtclam/model/stl/MX28T.dae" scale="0.00000002555635319 0.00000002555635319 0.00000002555635319 "/>
      </geometry>
    </visual>
    <collision>
      <!-- 0.012: Distance from MX28 axis to edge; Dynamixel outer dimensions: 0.0506x0.0356x0.041 (LxWxH) -->
      <origin rpy="0 0 0" xyz="0.0133 0 0"/>
      <geometry>
        <box size="0.0506 .0356 0.041"/>
      </geometry>
    </collision>
    <collision>
      <origin rpy="1.57079632679 0 1.57079632679" xyz="0.06075   -0.012 0"/>
      <geometry>
        <box size="0.0506 .0356 0.041"/>
      </geometry>
    </collision>
  </link>
  <gazebo reference="wrist_pitch_link">
    <material>Gazebo/Black</material>
  </gazebo>
  <joint name="joint6" type="revolute">
    <parent link="wrist_pitch_link"/>
    <child link="gripper_roll_link"/>
    <!-- y should be 0.004, but if we set this to 0, FastIK works much faster -->
    <origin oldrpy="4.71238898038 -1.57079632679 0" oldxyz="0 0 0.080" rpy="0 0 0" xyz="0.0783 0.0 0.0"/>
    <!-- Height of frame FR07-X101: 7mm from drawing -->
    <axis xyz="1 0 0"/>
    <limit effort="300" lower="-3.14159265359" upper="3.14159265359" velocity="1"/>
    <dynamics damping="50" friction="1"/>
  </joint>
  <!-- GRIPPER ROLL LINK -->
  <link name="gripper_roll_link">
  </link>
  <gazebo reference="gripper_roll_link">
    <material>Gazebo/Orange</material>
  </gazebo>
  <!-- Include Tools -->
  <!-- Transmissions for ROS Control -->
  <transmission name="tran1">
    <type>transmission_interface/SimpleTransmission</type>
    <joint name="joint0"/>
    <actuator name="motor1">
      <hardwareInterface>EffortJointInterface</hardwareInterface>
      <mechanicalReduction>1</mechanicalReduction>
    </actuator>
  </transmission>
  <transmission name="tran1">
    <type>transmission_interface/SimpleTransmission</type>
    <joint name="joint1"/>
    <actuator name="motor1">
      <hardwareInterface>EffortJointInterface</hardwareInterface>
      <mechanicalReduction>1</mechanicalReduction>
    </actuator>
  </transmission>
  <transmission name="tran1">
    <type>transmission_interface/SimpleTransmission</type>
    <joint name="joint2"/>
    <actuator name="motor1">
      <hardwareInterface>EffortJointInterface</hardwareInterface>
      <mechanicalReduction>1</mechanicalReduction>
    </actuator>
  </transmission>
  <transmission name="tran1">
    <type>transmission_interface/SimpleTransmission</type>
    <joint name="joint3"/>
    <actuator name="motor1">
      <hardwareInterface>EffortJointInterface</hardwareInterface>
      <mechanicalReduction>1</mechanicalReduction>
    </actuator>
  </transmission>
  <transmission name="tran1">
    <type>transmission_interface/SimpleTransmission</type>
    <joint name="joint4"/>
    <actuator name="motor1">
      <hardwareInterface>EffortJointInterface</hardwareInterface>
      <mechanicalReduction>1</mechanicalReduction>
    </actuator>
  </transmission>
  <transmission name="tran1">
    <type>transmission_interface/SimpleTransmission</type>
    <joint name="joint5"/>
    <actuator name="motor1">
      <hardwareInterface>EffortJointInterface</hardwareInterface>
      <mechanicalReduction>1</mechanicalReduction>
    </actuator>
  </transmission>
  <transmission name="tran1">
    <type>transmission_interface/SimpleTransmission</type>
    <joint name="joint6"/>
    <actuator name="motor1">
      <hardwareInterface>EffortJointInterface</hardwareInterface>
      <mechanicalReduction>1</mechanicalReduction>
    </actuator>
  </transmission>
  <transmission name="tran1">
    <type>transmission_interface/SimpleTransmission</type>
    <joint name="gripper_finger_joint"/>
    <actuator name="motor1">
      <hardwareInterface>EffortJointInterface</hardwareInterface>
      <mechanicalReduction>1</mechanicalReduction>
    </actuator>
  </transmission>
  <!-- ros_control plugin -->
  <gazebo>
    <plugin filename="libgazebo_ros_control.so" name="gazebo_ros_control">
      <robotNamespace>/clam</robotNamespace>
    </plugin>
  </gazebo>
</robot>

